INFO:     Started server process [2419220]
INFO:     Waiting for application startup.
2025-09-29 18:11:20,025 | INFO | app.session_manager | Starting session manager
2025-09-29 18:11:20,026 | INFO | app.sensors.tof | Starting ToF polling threshold=450 debounce_ms=200 interval_ms=50
INFO:     Application startup complete.
INFO:     Uvicorn running on http://0.0.0.0:5000 (Press CTRL+C to quit)
INFO:     ('127.0.0.1', 54524) - "WebSocket /ws/ui" [accepted]
INFO:     connection open
INFO:     connection closed
ERROR:    Exception in ASGI application
Traceback (most recent call last):
  File "/home/ichiro/.pyenv/versions/3.11.13/lib/python3.11/site-packages/uvicorn/protocols/websockets/websockets_impl.py", line 247, in run_asgi
    result = await self.app(self.scope, self.asgi_receive, self.asgi_send)
             ^^^^^^^^^^^^^^^^^^^^^^^^^^^^^^^^^^^^^^^^^^^^^^^^^^^^^^^^^^^^^
  File "/home/ichiro/.pyenv/versions/3.11.13/lib/python3.11/site-packages/uvicorn/middleware/proxy_headers.py", line 84, in __call__
    return await self.app(scope, receive, send)
           ^^^^^^^^^^^^^^^^^^^^^^^^^^^^^^^^^^^^
  File "/home/ichiro/.pyenv/versions/3.11.13/lib/python3.11/site-packages/fastapi/applications.py", line 1106, in __call__
    await super().__call__(scope, receive, send)
  File "/home/ichiro/.pyenv/versions/3.11.13/lib/python3.11/site-packages/starlette/applications.py", line 122, in __call__
    await self.middleware_stack(scope, receive, send)
  File "/home/ichiro/.pyenv/versions/3.11.13/lib/python3.11/site-packages/starlette/middleware/errors.py", line 149, in __call__
    await self.app(scope, receive, send)
  File "/home/ichiro/.pyenv/versions/3.11.13/lib/python3.11/site-packages/starlette/middleware/cors.py", line 75, in __call__
    await self.app(scope, receive, send)
  File "/home/ichiro/.pyenv/versions/3.11.13/lib/python3.11/site-packages/starlette/middleware/exceptions.py", line 79, in __call__
    raise exc
  File "/home/ichiro/.pyenv/versions/3.11.13/lib/python3.11/site-packages/starlette/middleware/exceptions.py", line 68, in __call__
    await self.app(scope, receive, sender)
  File "/home/ichiro/.pyenv/versions/3.11.13/lib/python3.11/site-packages/fastapi/middleware/asyncexitstack.py", line 20, in __call__
    raise e
  File "/home/ichiro/.pyenv/versions/3.11.13/lib/python3.11/site-packages/fastapi/middleware/asyncexitstack.py", line 17, in __call__
    await self.app(scope, receive, send)
  File "/home/ichiro/.pyenv/versions/3.11.13/lib/python3.11/site-packages/starlette/routing.py", line 718, in __call__
    await route.handle(scope, receive, send)
  File "/home/ichiro/.pyenv/versions/3.11.13/lib/python3.11/site-packages/starlette/routing.py", line 341, in handle
    await self.app(scope, receive, send)
  File "/home/ichiro/.pyenv/versions/3.11.13/lib/python3.11/site-packages/starlette/routing.py", line 82, in app
    await func(session)
  File "/home/ichiro/.pyenv/versions/3.11.13/lib/python3.11/site-packages/fastapi/routing.py", line 325, in app
    await dependant.call(**values)
  File "/home/ichiro/Desktop/mercleapp/mDai/frontend/mdaitest/controller/app/main.py", line 122, in ui_socket
    await ws.send_json(payload)
  File "/home/ichiro/.pyenv/versions/3.11.13/lib/python3.11/site-packages/starlette/websockets.py", line 173, in send_json
    await self.send({"type": "websocket.send", "text": text})
  File "/home/ichiro/.pyenv/versions/3.11.13/lib/python3.11/site-packages/starlette/websockets.py", line 85, in send
    await self._send(message)
  File "/home/ichiro/.pyenv/versions/3.11.13/lib/python3.11/site-packages/starlette/middleware/exceptions.py", line 65, in sender
    await send(message)
  File "/home/ichiro/.pyenv/versions/3.11.13/lib/python3.11/site-packages/uvicorn/protocols/websockets/websockets_impl.py", line 320, in asgi_send
    await self.send(data)  # type: ignore[arg-type]
    ^^^^^^^^^^^^^^^^^^^^^
  File "/home/ichiro/.pyenv/versions/3.11.13/lib/python3.11/site-packages/websockets/legacy/protocol.py", line 620, in send
    await self.ensure_open()
  File "/home/ichiro/.pyenv/versions/3.11.13/lib/python3.11/site-packages/websockets/legacy/protocol.py", line 921, in ensure_open
    raise self.connection_closed_exc()
websockets.exceptions.ConnectionClosedOK: received 1001 (going away); then sent 1001 (going away)
